Workbook

Sheet 主站
A1: # | B1: Title | C1: 标题 | D1: 链接 | E1: 是否会员 | F1: 分类 | G1: 等级 | H1: 进阶等级 | I1: 难度 | J1: 竞赛
A2: 1 | B2: Two Sum | C2: 两数之和 | D2: https://leetcode.cn/problems/two-sum/ | E2: 0 | F2: Algorithms | G2: 2 | H2: 2 | I2: Easy
A3: 2 | B3: Add Two Numbers | C3: 两数相加 | D3: https://leetcode.cn/problems/add-two-numbers/ | E3: 0 | F3: Algorithms | G3: 3 | H3: 0 | I3: Medium
A4: 3 | B4: Longest Substring Without Repeating Characters | C4: 无重复字符的最长子串 | D4: https://leetcode.cn/problems/longest-substring-without-repeating-characters/ | E4: 0 | F4: Algorithms | G4: 5 | H4: 0 | I4: Medium
A5: 4 | B5: Median of Two Sorted Arrays | C5: 寻找两个正序数组的中位数 | D5: https://leetcode.cn/problems/median-of-two-sorted-arrays/ | E5: 0 | F5: Algorithms | G5: 8 | H5: 0 | I5: Hard
A6: 5 | B6: Longest Palindromic Substring | C6: 最长回文子串 | D6: https://leetcode.cn/problems/longest-palindromic-substring/ | E6: 0 | F6: Algorithms | G6: 5 | H6: 0 | I6: Medium
A7: 6 | B7: Zigzag Conversion | C7: Z 字形变换 | D7: https://leetcode.cn/problems/zigzag-conversion/ | E7: 0 | F7: Algorithms | G7: 4 | H7: 0 | I7: Medium
A8: 7 | B8: Reverse Integer | C8: 整数反转 | D8: https://leetcode.cn/problems/reverse-integer/ | E8: 0 | F8: Algorithms | G8: 5 | H8: 0 | I8: Medium
A9: 8 | B9: String to Integer (atoi) | C9: 字符串转换整数 (atoi) | D9: https://leetcode.cn/problems/string-to-integer-atoi/ | E9: 0 | F9: Algorithms | G9: 6 | H9: 0 | I9: Medium
A10: 9 | B10: Palindrome Number | C10: 回文数 | D10: https://leetcode.cn/problems/palindrome-number/ | E10: 0 | F10: Algorithms | G10: 2 | H10: 3 | I10: Easy
A11: 10 | B11: Regular Expression Matching | C11: 正则表达式匹配 | D11: https://leetcode.cn/problems/regular-expression-matching/ | E11: 0 | F11: Algorithms | G11: 8 | H11: 0 | I11: Hard
A12: 11 | B12: Container With Most Water | C12: 盛最多水的容器 | D12: https://leetcode.cn/problems/container-with-most-water/ | E12: 0 | F12: Algorithms | G12: 4 | H12: 0 | I12: Medium
A13: 12 | B13: Integer to Roman | C13: 整数转罗马数字 | D13: https://leetcode.cn/problems/integer-to-roman/ | E13: 0 | F13: Algorithms | G13: 3 | H13: 0 | I13: Medium
... A386: 385 | B386: Mini Parser | C386: 迷你语法分析器 | D386: https://leetcode.cn/problems/mini-parser/ | E386: 0 | F386: Algorithms | G386: 6 | H386: 0 | I386: Medium
A387: 386 | B387: Lexicographical Numbers | C387: 字典序排数 | D387: https://leetcode.cn/problems/lexicographical-numbers/ | E387: 0 | F387: Algorithms | G387: 6 | H387: 0 | I387: Medium | J387: Warm Up Contest 1 Problem 1
A388: 387 | B388: First Unique Character in a String | C388: 字符串中的第一个唯一字符 | D388: https://leetcode.cn/problems/first-unique-character-in-a-string/ | E388: 0 | F388: Algorithms | G388: 3 | H388: 0 | I388: Easy | J388: Warm Up Contest 1 Problem 2
A389: 388 | B389: Longest Absolute File Path | C389: 文件的最长绝对路径 | D389: https://leetcode.cn/problems/longest-absolute-file-path/ | E389: 0 | F389: Algorithms | G389: 7 | H389: 0 | I389: Medium | J389: Warm Up Contest 1 Problem 3
A390: 389 | B390: Find the Difference | C390: 找不同 | D390: https://leetcode.cn/problems/find-the-difference/ | E390: 0 | F390: Algorithms | G390: 2 | H390: 0 | I390: Easy | J390: Weekly Contest 2 Problem 1
A391: 390 | B391: Elimination Game | C391: 消除游戏 | D391: https://leetcode.cn/problems/elimination-game/ | E391: 0 | F391: Algorithms | G391: 6 | H391: 0 | I391: Medium | J391: Weekly Contest 2 Problem 2
A392: 391 | B392: Perfect Rectangle | C392: 完美矩形 | D392: https://leetcode.cn/problems/perfect-rectangle/ | E392: 0 | F392: Algorithms | G392: 8 | H392: 0 | I392: Hard | J392: Weekly Contest 2 Problem 3
A393: 392 | B393: Is Subsequence | C393: 判断子序列 | D393: https://leetcode.cn/problems/is-subsequence/ | E393: 0 | F393: Algorithms | G393: 3 | H393: 7 | I393: Easy | J393: Weekly Contest 3 Problem 1
A394: 393 | B394: UTF-8 Validation | C394: UTF-8 编码验证 | D394: https://leetcode.cn/problems/utf-8-validation/ | E394: 0 | F394: Algorithms | G394: 4 | H394: 0 | I394: Medium | J394: Weekly Contest 3 Problem 2
A395: 394 | B395: Decode String | C395: 字符串解码 | D395: https://leetcode.cn/problems/decode-string/ | E395: 0 | F395: Algorithms | G395: 6 | H395: 0 | I395: Medium | J395: Weekly Contest 3 Problem 3
A396: 395 | B396: Longest Substring with At Least K Repeating Characters | C396: 至少有K个重复字符的最长子串 | D396: https://leetcode.cn/problems/longest-substring-with-at-least-k-repeating-characters/ | E396: 0 | F396: Algorithms | G396: 6 | H396: 0 | I396: Medium | J396: Weekly Contest 3 Problem 4
A397: 396 | B397: Rotate Function | C397: 旋转函数 | D397: https://leetcode.cn/problems/rotate-function/ | E397: 0 | F397: Algorithms | G397: 5 | H397: 0 | I397: Medium | J397: Weekly Contest 4 Problem 1
A398: 397 | B398: Integer Replacement | C398: 整数替换 | D398: https://leetcode.cn/problems/integer-replacement/ | E398: 0 | F398: Algorithms | G398: 5 | H398: 0 | I398: Medium | J398: Weekly Contest 4 Problem 2
... A412: 411 | B412: Minimum Unique Word Abbreviation | C412: 最短独占单词缩写 | D412: https://leetcode.cn/problems/minimum-unique-word-abbreviation/ | E412: 1 | F412: Algorithms | G412: 6 | H412: 0 | I412: Hard | J412: Weekly Contest 7 Problem 4
A413: 412 | B413: Fizz Buzz | C413: Fizz Buzz | D413: https://leetcode.cn/problems/fizz-buzz/ | E413: 0 | F413: Algorithms | G413: 2 | H413: 0 | I413: Easy
A414: 413 | B414: Arithmetic Slices | C414: 等差数列划分 | D414: https://leetcode.cn/problems/arithmetic-slices/ | E414: 0 | F414: Algorithms | G414: 4 | H414: 0 | I414: Medium
A415: 414 | B415: Third Maximum Number | C415: 第三大的数 | D415: https://leetcode.cn/problems/third-maximum-number/ | E415: 0 | F415: Algorithms | G415: 3 | H415: 3 | I415: Easy
A416: 415 | B416: Add Strings | C416: 字符串相加 | D416: https://leetcode.cn/problems/add-strings/ | E416: 0 | F416: Algorithms | G416: 3 | H416: 0 | I416: Easy | J416: Weekly Contest 8 Problem 1
A417: 416 | B417: Partition Equal Subset Sum | C417: 分割等和子集 | D417: https://leetcode.cn/problems/partition-equal-subset-sum/ | E417: 0 | F417: Algorithms | G417: 5 | H417: 0 | I417: Medium | J417: Weekly Contest 8 Problem 2
A418: 417 | B418: Pacific Atlantic Water Flow | C418: 太平洋大西洋水流问题 | D418: https://leetcode.cn/problems/pacific-atlantic-water-flow/ | E418: 0 | F418: Algorithms | G418: 5 | H418: 0 | I418: Medium | J418: Weekly Contest 8 Problem 3
A419: 418 | B419: Sentence Screen Fitting | C419: 屏幕可显示句子的数量 | D419: https://leetcode.cn/problems/sentence-screen-fitting/ | E419: 1 | F419: Algorithms | G419: 7 | H419: 0 | I419: Medium | J419: Weekly Contest 8 Problem 4
A420: 419 | B420: Battleships in a Board | C420: 甲板上的战舰 | D420: https://leetcode.cn/problems/battleships-in-a-board/ | E420: 0 | F420: Algorithms | G420: 4 | H420: 4 | I420: Medium
A421: 420 | B421: Strong Password Checker | C421: 强密码检验器 | D421: https://leetcode.cn/problems/strong-password-checker/ | E421: 0 | F421: Algorithms | G421: 10 | H421: 0 | I421: Hard
A422: 421 | B422: Maximum XOR of Two Numbers in an Array | C422: 数组中两个数的最大异或值 | D422: https://leetcode.cn/problems/maximum-xor-of-two-numbers-in-an-array/ | E422: 0 | F422: Algorithms | G422: 8 | H422: 0 | I422: Medium
A423: 422 | B423: Valid Word Square | C423: 有效的单词方块 | D423: https://leetcode.cn/problems/valid-word-square/ | E423: 1 | F423: Algorithms | G423: 4 | H423: 0 | I423: Easy | J423: Weekly Contest 9 Problem 1
A424: 423 | B424: Reconstruct Original Digits from English | C424: 从英文中重建数字 | D424: https://leetcode.cn/problems/reconstruct-original-digits-from-english/ | E424: 0 | F424: Algorithms | G424: 4 | H424: 0 | I424: Medium | J424: Weekly Contest 9 Problem 2
A425: 424 | B425: Longest Repeating Character Replacement | C425: 替换后的最长重复字符 | D425: https://leetcode.cn/problems/longest-repeating-character-replacement/ | E425: 0 | F425: Algorithms | G425: 6 | H425: 0 | I425: Medium | J425: Weekly Contest 9 Problem 3
...

Sheet LCP
A1: # | B1: 标题 | C1: 链接 | D1: 是否会员 | E1: 分类 | F1: 等级 | G1: 进阶等级 | H1: 难度 | I1: 竞赛
A2: LCP 01 | B2: 猜数字 | C2: https://leetcode.cn/problems/guess-numbers/ | D2: 0 | E2: Algorithms | F2: 1 | G2: 0 | H2: Easy | I2: LCP 2019 Fall Problem 1
A3: LCP 02 | B3: 分式化简 | C3: https://leetcode.cn/problems/deep-dark-fraction/ | D3: 0 | E3: Algorithms | F3: 4 | G3: 0 | H3: Easy | I3: LCP 2019 Fall Problem 2
A4: LCP 03 | B4: 机器人大冒险 | C4: https://leetcode.cn/problems/programmable-robot/ | D4: 0 | E4: Algorithms | F4: 6 | G4: 0 | H4: Medium | I4: LCP 2019 Fall Problem 3
A5: LCP 04 | B5: 覆盖 | C5: https://leetcode.cn/problems/broken-board-dominoes/ | D5: 0 | E5: Algorithms | F5: 8 | G5: 0 | H5: Hard | I5: LCP 2019 Fall Problem 4
A6: LCP 05 | B6: 发 LeetCoin | C6: https://leetcode.cn/problems/coin-bonus/ | D6: 0 | E6: Algorithms | F6: 10 | G6: 0 | H6: Hard | I6: LCP 2019 Fall Problem 5
A7: LCP 06 | B7: 拿硬币 | C7: https://leetcode.cn/problems/na-ying-bi/ | D7: 0 | E7: Algorithms | F7: 2 | G7: 0 | H7: Easy | I7: LCP 2020 Spring Solo Problem 1
A8: LCP 07 | B8: 传递信息 | C8: https://leetcode.cn/problems/chuan-di-xin-xi/ | D8: 0 | E8: Algorithms | F8: 4 | G8: 0 | H8: Easy | I8: LCP 2020 Spring Solo Problem 2
A9: LCP 08 | B9: 剧情触发时间 | C9: https://leetcode.cn/problems/ju-qing-hong-fa-shi-jian/ | D9: 0 | E9: Algorithms | F9: 7 | G9: 0 | H9: Medium | I9: LCP 2020 Spring Solo Problem 3
A10: LCP 09 | B10: 最小跳跃次数 | C10: https://leetcode.cn/problems/zui-xiao-tiao-yue-ci-shu/ | D10: 0 | E10: Algorithms | F10: 8 | G10: 0 | H10: Hard | I10: LCP 2020 Spring Solo Problem 4
A11: LCP 10 | B11: 二叉树任务调度 | C11: https://leetcode.cn/problems/er-cha-shu-ren-wu-diao-du/ | D11: 0 | E11: Algorithms | F11: 10 | G11: 0 | H11: Hard | I11: LCP 2020 Spring Solo Problem 5
A12: LCP 11 | B12: 期望个数统计 | C12: https://leetcode.cn/problems/qi-wang-ge-shu-tong-ji/ | D12: 0 | E12: Algorithms | F12: 3 | G12: 0 | H12: Easy | I12: LCP 2020 Spring Team Problem 1
A13: LCP 12 | B13: 小张刷题计划 | C13: https://leetcode.cn/problems/xiao-zhang-shua-ti-ji-hua/ | D13: 0 | E13: Algorithms | F13: 6 | G13: 0 | H13: Medium | I13: LCP 2020 Spring Team Problem 2
... A83: LCP 82 | B83: 万灵之树 | C83: https://leetcode.cn/problems/cnHoX6/ | D83: 0 | E83: Algorithms | F83: 11 | G83: 0 | H83: Hard | I83: LCP 2023 Spring Team Problem 6

Sheet LCS
A1: # | B1: 标题 | C1: 链接 | D1: 是否会员 | E1: 分类 | F1: 等级 | G1: 进阶等级 | H1: 难度
A2: LCS 01 | B2: 下载插件 | C2: https://leetcode.cn/problems/Ju9Xwi/ | D2: 0 | E2: Algorithms | F2: 3 | G2: 0 | H2: Easy
A3: LCS 02 | B3: 完成一半题目 | C3: https://leetcode.cn/problems/WqXACV/ | D3: 0 | E3: Algorithms | F3: 3 | G3: 0 | H3: Easy
A4: LCS 03 | B4: 主题空间 | C4: https://leetcode.cn/problems/YesdPw/ | D4: 0 | E4: Algorithms | F4: 5 | G4: 0 | H4: Medium

Sheet 剑指Offer
A1: # | B1: 标题 | C1: 链接 | D1: 等级 | E1: 难度
A2: 3 | B2: 数组中重复的数字 | C2: https://leetcode.cn/problems/shu-zu-zhong-zhong-fu-de-shu-zi-lcof/ | D2: 3 | E2: Easy
A3: 4 | B3: 二维数组中的查找 | C3: https://leetcode.cn/problems/er-wei-shu-zu-zhong-de-cha-zhao-lcof/ | D3: 5 | E3: Medium
A4: 5 | B4: 替换空格 | C4: https://leetcode.cn/problems/ti-huan-kong-ge-lcof/ | D4: 3 | E4: Easy
A5: 6 | B5: 从尾到头打印链表 | C5: https://leetcode.cn/problems/cong-wei-dao-tou-da-yin-lian-biao-lcof/ | D5: 3 | E5: Easy
A6: 7 | B6: 重建二叉树 | C6: https://leetcode.cn/problems/zhong-jian-er-cha-shu-lcof/ | D6: 5 | E6: Medium
A7: 9 | B7: 用两个栈实现队列 | C7: https://leetcode.cn/problems/yong-liang-ge-zhan-shi-xian-dui-lie-lcof/ | D7: 4 | E7: Easy
A8: 10-I | B8: 斐波那契数列 | C8: https://leetcode.cn/problems/fei-bo-na-qi-shu-lie-lcof/ | D8: 2 | E8: Easy
A9: 10-II | B9: 青蛙跳台阶问题 | C9: https://leetcode.cn/problems/qing-wa-tiao-tai-jie-wen-ti-lcof/ | D9: 2 | E9: Easy
A10: 11 | B10: 旋转数组的最小数字 | C10: https://leetcode.cn/problems/xuan-zhuan-shu-zu-de-zui-xiao-shu-zi-lcof/ | D10: 6 | E10: Easy
A11: 12 | B11: 矩阵中的路径 | C11: https://leetcode.cn/problems/ju-zhen-zhong-de-lu-jing-lcof/ | D11: 4 | E11: Medium
A12: 13 | B12: 机器人的运动范围 | C12: https://leetcode.cn/problems/ji-qi-ren-de-yun-dong-fan-wei-lcof/ | D12: 4 | E12: Medium
A13: 14-I | B13: 剪绳子 | C13: https://leetcode.cn/problems/jian-sheng-zi-lcof/ | D13: 4 | E13: Medium
A14: 14-II | B14: 剪绳子 II | C14: https://leetcode.cn/problems/jian-sheng-zi-ii-lcof/ | D14: 4 | E14: Medium
A15: 15 | B15: 二进制中1的个数 | C15: https://leetcode.cn/problems/er-jin-zhi-zhong-1de-ge-shu-lcof/ | D15: 2 | E15: Easy
A16: 16 | B16: 数值的整数次方 | C16: https://leetcode.cn/problems/shu-zhi-de-zheng-shu-ci-fang-lcof/ | D16: 5 | E16: Medium
A17: 17 | B17: 打印从1到最大的n位数 | C17: https://leetcode.cn/problems/da-yin-cong-1dao-zui-da-de-nwei-shu-lcof/ | D17: 3 | E17: Easy
A18: 18 | B18: 删除链表的节点 | C18: https://leetcode.cn/problems/shan-chu-lian-biao-de-jie-dian-lcof/ | D18: 3 | E18: Easy
A19: 19 | B19: 正则表达式匹配 | C19: https://leetcode.cn/problems/zheng-ze-biao-da-shi-pi-pei-lcof/ | D19: 8 | E19: Hard
A20: 20 | B20: 表示数值的字符串 | C20: https://leetcode.cn/problems/biao-shi-shu-zhi-de-zi-fu-chuan-lcof/ | D20: 8 | E20: Medium
A21: 21 | B21: 调整数组顺序使奇数位于偶数前面 | C21: https://leetcode.cn/problems/diao-zheng-shu-zu-shun-xu-shi-qi-shu-wei-yu-ou-shu-qian-mian-lcof/ | D21: 3 | E21: Easy
A22: 22 | B22: 链表中倒数第k个节点 | C22: https://leetcode.cn/problems/lian-biao-zhong-dao-shu-di-kge-jie-dian-lcof/ | D22: 2 | E22: Easy
A23: 24 | B23: 反转链表 | C23: https://leetcode.cn/problems/fan-zhuan-lian-biao-lcof/ | D23: 3 | E23: Easy
A24: 25 | B24: 合并两个排序的链表 | C24: https://leetcode.cn/problems/he-bing-liang-ge-pai-xu-de-lian-biao-lcof/ | D24: 3 | E24: Easy
A25: 26 | B25: 树的子结构 | C25: https://leetcode.cn/problems/shu-de-zi-jie-gou-lcof/ | D25: 4 | E25: Medium
A26: 27 | B26: 二叉树的镜像 | C26: https://leetcode.cn/problems/er-cha-shu-de-jing-xiang-lcof/ | D26: 3 | E26: Easy
... A30: 31 | B30: 栈的压入、弹出序列 | C30: https://leetcode.cn/problems/zhan-de-ya-ru-dan-chu-xu-lie-lcof/ | D30: 5 | E30: Medium
A31: 32-I | B31: 从上到下打印二叉树 | C31: https://leetcode.cn/problems/cong-shang-dao-xia-da-yin-er-cha-shu-lcof/ | D31: 3 | E31: Medium
A32: 32-II | B32: 从上到下打印二叉树 II | C32: https://leetcode.cn/problems/cong-shang-dao-xia-da-yin-er-cha-shu-ii-lcof/ | D32: 4 | E32: Easy
A33: 32-III | B33: 从上到下打印二叉树 III | C33: https://leetcode.cn/problems/cong-shang-dao-xia-da-yin-er-cha-shu-iii-lcof/ | D33: 4 | E33: Medium
A34: 33 | B34: 二叉搜索树的后序遍历序列 | C34: https://leetcode.cn/problems/er-cha-sou-suo-shu-de-hou-xu-bian-li-xu-lie-lcof/ | D34: 6 | E34: Medium
A35: 34 | B35: 二叉树中和为某一值的路径 | C35: https://leetcode.cn/problems/er-cha-shu-zhong-he-wei-mou-yi-zhi-de-lu-jing-lcof/ | D35: 4 | E35: Medium
A36: 35 | B36: 复杂链表的复制 | C36: https://leetcode.cn/problems/fu-za-lian-biao-de-fu-zhi-lcof/ | D36: 6 | E36: Medium
A37: 36 | B37: 二叉搜索树与双向链表 | C37: https://leetcode.cn/problems/er-cha-sou-suo-shu-yu-shuang-xiang-lian-biao-lcof/ | D37: 4 | E37: Medium
A38: 37 | B38: 序列化二叉树 | C38: https://leetcode.cn/problems/xu-lie-hua-er-cha-shu-lcof/ | D38: 8 | E38: Hard
A39: 38 | B39: 字符串的排列 | C39: https://leetcode.cn/problems/zi-fu-chuan-de-pai-lie-lcof/ | D39: 5 | E39: Medium
A40: 39 | B40: 数组中出现次数超过一半的数字 | C40: https://leetcode.cn/problems/shu-zu-zhong-chu-xian-ci-shu-chao-guo-yi-ban-de-shu-zi-lcof/ | D40: 2 | E40: Easy
A41: 40 | B41: 最小的k个数 | C41: https://leetcode.cn/problems/zui-xiao-de-kge-shu-lcof/ | D41: 3 | E41: Easy
A42: 41 | B42: 数据流中的中位数 | C42: https://leetcode.cn/problems/shu-ju-liu-zhong-de-zhong-wei-shu-lcof/ | D42: 6 | E42: Hard
A43: 42 | B43: 连续子数组的最大和 | C43: https://leetcode.cn/problems/lian-xu-zi-shu-zu-de-zui-da-he-lcof/ | D43: 3 | E43: Easy
...

Sheet 剑指Offer专项突破版
A1: # | B1: 标题 | C1: 链接 | D1: 等级 | E1: 进阶等级 | F1: 难度
A2: 1 | B2: 整数除法 | C2: https://leetcode.cn/problems/xoh6Oh/ | D2: =主站!G30 -> 6 | E2: =主站!H30 -> 0 | F2: Easy
A3: 2 | B3: 二进制加法 | C3: https://leetcode.cn/problems/JFETK5/ | D3: =主站!G68 -> 3 | E3: =主站!H68 -> 0 | F3: Easy
A4: 3 | B4: 前 n 个数字二进制中 1 的个数 | C4: https://leetcode.cn/problems/w3tCBm/ | D4: =主站!G339 -> 2 | E4: =主站!H339 -> 5 | F4: Easy
A5: 4 | B5: 只出现一次的数字 | C5: https://leetcode.cn/problems/WGki4K/ | D5: =主站!G138 -> 6 | E5: =主站!H138 -> 0 | F5: Medium
A6: 5 | B6: 单词长度的最大乘积 | C6: https://leetcode.cn/problems/aseY1I/ | D6: =主站!G319 -> 4 | E6: =主站!H319 -> 0 | F6: Medium
A7: 6 | B7: 排序数组中两个数字之和 | C7: https://leetcode.cn/problems/kLl5u1/ | D7: =主站!G168 -> 3 | E7: =主站!H168 -> 0 | F7: Easy
A8: 7 | B8: 数组中和为 0 的三个数 | C8: https://leetcode.cn/problems/1fGaJU/ | D8: =主站!G16 -> 4 | E8: =主站!H16 -> 0 | F8: Medium
A9: 8 | B9: 和大于等于 target 的最短子数组 | C9: https://leetcode.cn/problems/2VG8Kg/ | D9: =主站!G210 -> 5 | E9: =主站!H210 -> 5 | F9: Medium
A10: 9 | B10: 乘积小于 K 的子数组 | C10: https://leetcode.cn/problems/ZVAVXX/ | D10: =主站!G714 -> 5 | E10: =主站!H714 -> 0 | F10: Medium
A11: 10 | B11: 和为 k 的子数组 | C11: https://leetcode.cn/problems/QTMn0o/ | D11: =主站!G561 -> 5 | E11: =主站!H561 -> 0 | F11: Medium
A12: 11 | B12: 0 和 1 个数相同的子数组 | C12: https://leetcode.cn/problems/A1NYOS/ | D12: =主站!G526 -> 5 | E12: =主站!H526 -> 0 | F12: Medium
A13: 12 | B13: 左右两边子数组的和相等 | C13: https://leetcode.cn/problems/tvdfij/ | D13: =主站!G725 -> 3 | E13: =主站!H725 -> 0 | F13: Easy
A14: 13 | B14: 二维子矩阵的和 | C14: https://leetcode.cn/problems/O4NDxx/ | D14: =主站!G305 -> 5 | E14: =主站!H305 -> 0 | F14: Medium
A15: 14 | B15: 字符串中的变位词 | C15: https://leetcode.cn/problems/MPnaiL/ | D15: =主站!G568 -> 4 | E15: =主站!H568 -> 0 | F15: Medium
A16: 15 | B16: 字符串中的所有变位词 | C16: https://leetcode.cn/problems/VabMRr/ | D16: =主站!G439 -> 4 | E16: =主站!H439 -> 0 | F16: Medium
A17: 16 | B17: 不含重复字符的最长子字符串 | C17: https://leetcode.cn/problems/wtcaE1/ | D17: =主站!G4 -> 5 | E17: =主站!H4 -> 0 | F17: Medium
A18: 17 | B18: 含有所有字符的最短字符串 | C18: https://leetcode.cn/problems/M1oyTv/ | D18: =主站!G77 -> 6 | E18: =主站!H77 -> 6 | F18: Hard
A19: 18 | B19: 有效的回文 | C19: https://leetcode.cn/problems/XltzEq/ | D19: =主站!G126 -> 3 | E19: =主站!H126 -> 0 | F19: Easy
A20: 19 | B20: 最多删除一个字符得到回文 | C20: https://leetcode.cn/problems/RQku0D/ | D20: =主站!G681 -> 3 | E20: =主站!H681 -> 0 | F20: Easy
A21: 20 | B21: 回文子字符串的个数 | C21: https://leetcode.cn/problems/a7VOhD/ | D21: =主站!G648 -> 5 | E21: =主站!H648 -> 0 | F21: Medium
A22: 21 | B22: 删除链表的倒数第 n 个结点 | C22: https://leetcode.cn/problems/SLwz0R/ | D22: =主站!G20 -> 3 | E22: =主站!H20 -> 4 | F22: Medium
A23: 22 | B23: 链表中环的入口节点 | C23: https://leetcode.cn/problems/c32eOV/ | D23: =主站!G143 -> 2 | E23: =主站!H143 -> 6 | F23: Medium
A24: 23 | B24: 两个链表的第一个重合节点 | C24: https://leetcode.cn/problems/3u1WK4/ | D24: =主站!G161 -> 2 | E24: =主站!H161 -> 4 | F24: Easy
A25: 24 | B25: 反转链表 | C25: https://leetcode.cn/problems/UHnkqh/ | D25: =主站!G207 -> 3 | E25: =主站!H207 -> 4 | F25: Easy
A26: 25 | B26: 链表中的两数相加 | C26: https://leetcode.cn/problems/lMSNwu/ | D26: =主站!G446 -> 4 | E26: =主站!H446 -> 4 | F26: Medium
A27: 26 | B27: 重排链表 | C27: https://leetcode.cn/problems/LGjMqU/ | D27: =主站!G144 -> 5 | E27: =主站!H144 -> 0 | F27: Medium
A28: 27 | B28: 回文链表 | C28: https://leetcode.cn/problems/aMhZSa/ | D28: =主站!G235 -> 3 | E28: =主站!H235 -> 5 | F28: Easy
A29: 28 | B29: 展平多级双向链表 | C29: https://leetcode.cn/problems/Qv1Da2/ | D29: =主站!G431 -> 7 | E29: =主站!H431 -> 0 | F29: Medium
A30: 29 | B30: 排序的循环链表 | C30: https://leetcode.cn/problems/4ueAj6/ | D30: =主站!G709 -> 5 | E30: =主站!H709 -> 0 | F30: Medium
A31: 30 | B31: 插入、删除和随机访问都是 O(1) 的容器 | C31: https://leetcode.cn/problems/FortPu/ | D31: =主站!G381 -> 6 | E31: =主站!H381 -> 0 | F31: Medium
A32: 31 | B32: 最近最少使用缓存 | C32: https://leetcode.cn/problems/OrIXps/ | D32: =主站!G147 -> 7 | E32: =主站!H147 -> 0 | F32: Medium
A33: 32 | B33: 有效的变位词 | C33: https://leetcode.cn/problems/dKk3P7/ | D33: =主站!G243 -> 2 | E33: =主站!H243 -> 3 | F33: Easy
A34: 33 | B34: 变位词组 | C34: https://leetcode.cn/problems/sfvd7V/ | D34: =主站!G50 -> 4 | E34: =主站!H50 -> 0 | F34: Medium
A35: 34 | B35: 外星语言是否排序 | C35: https://leetcode.cn/problems/lwyVBB/ | D35: =主站!G954 -> 3 | E35: =主站!H954 -> 0 | F35: Easy
A36: 35 | B36: 最小时间差 | C36: https://leetcode.cn/problems/569nqc/ | D36: =主站!G540 -> 3 | E36: =主站!H540 -> 0 | F36: Medium
A37: 36 | B37: 后缀表达式 | C37: https://leetcode.cn/problems/8Zf90G/ | D37: =主站!G151 -> 4 | E37: =主站!H151 -> 0 | F37: Medium
A38: 37 | B38: 小行星碰撞 | C38: https://leetcode.cn/problems/XagZNi/ | D38: =主站!G736 -> 5 | E38: =主站!H736 -> 0 | F38: Medium
A39: 38 | B39: 每日温度 | C39: https://leetcode.cn/problems/iIQa4I/ | D39: =主站!G740 -> 6 | E39: =主站!H740 -> 0 | F39: Medium
A40: 39 | B40: 直方图最大矩形面积 | C40: https://leetcode.cn/problems/0ynMMM/ | D40: =主站!G85 -> 7 | E40: =主站!H85 -> 0 | F40: Hard
...

Sheet 程序员面试金典
A1: # | B1: 标题 | C1: 链接 | D1: 等级 | E1: 进阶等级 | F1: 难度
A2: 面试题 01.01 | B2: 判定字符是否唯一 | C2: https://leetcode.cn/problems/is-unique-lcci/ | D2: 2 | E2: 3 | F2: Easy
A3: 面试题 01.02 | B3: 判定是否互为字符重排 | C3: https://leetcode.cn/problems/check-permutation-lcci/ | D3: 2 | E3: 0 | F3: Easy
A4: 面试题 01.03 | B4: URL化 | C4: https://leetcode.cn/problems/string-to-url-lcci/ | D4: 3 | E4: 0 | F4: Easy
A5: 面试题 01.04 | B5: 回文排列 | C5: https://leetcode.cn/problems/palindrome-permutation-lcci/ | D5: 3 | E5: 0 | F5: Easy
A6: 面试题 01.05 | B6: 一次编辑 | C6: https://leetcode.cn/problems/one-away-lcci/ | D6: 4 | E6: 0 | F6: Medium
A7: 面试题 01.06 | B7: 字符串压缩 | C7: https://leetcode.cn/problems/compress-string-lcci/ | D7: 4 | E7: 0 | F7: Easy
A8: 面试题 01.07 | B8: 旋转矩阵 | C8: https://leetcode.cn/problems/rotate-matrix-lcci/ | D8: 5 | E8: 0 | F8: Medium
A9: 面试题 01.08 | B9: 零矩阵 | C9: https://leetcode.cn/problems/zero-matrix-lcci/ | D9: 3 | E9: 0 | F9: Medium
A10: 面试题 01.09 | B10: 字符串轮转 | C10: https://leetcode.cn/problems/string-rotation-lcci/ | D10: 3 | E10: 0 | F10: Easy
A11: 面试题 02.01 | B11: 移除重复节点 | C11: https://leetcode.cn/problems/remove-duplicate-node-lcci/ | D11: 3 | E11: 4 | F11: Easy
A12: 面试题 02.02 | B12: 返回倒数第 k 个节点 | C12: https://leetcode.cn/problems/kth-node-from-end-of-list-lcci/ | D12: 2 | E12: 0 | F12: Easy
A13: 面试题 02.03 | B13: 删除中间节点 | C13: https://leetcode.cn/problems/delete-middle-node-lcci/ | D13: 3 | E13: 0 | F13: Easy
... A110: 面试题 17.26 | B110: 稀疏相似度 | C110: https://leetcode.cn/problems/sparse-similarity-lcci/ | D110: 8 | E110: 0 | F110: Hard
